Workbook

Sheet 说明
A1: 赛可心理测试测评主题 · 测评题目与维度设计总表
A3: 覆盖范围：391 个测评主题（与《psyctest_测评主题.xlsx》序号一致），共 10,275 道原创题目
A4: 生成时间：2026-10-01；题目为本项目原创设计，未抄录任何真实量表原文
A6: 工作表结构：
A7: ① 主题总览：每个主题一行（题数、维度数由公式统计）
A8: ② 题目明细：每道题一行，含题干、题型、所属维度、各选项文本与分值
A9: ③ 维度设置：每个维度一行，含说明、包含题号、最低分/总分（公式汇总）
A10: ④ 分数段分析：每个维度 3-5 个分数段，含评级、分析解读与建议
A12: 计分口径：
A13: · 单选题：得分为所选选项的分值。情景/趣味类单选 4-5 个选项分值为 1..n 的排列；
A14: · 频率自评类单选：选项固定 从不/偶尔/经常/总是（1-4 分），反向陈述题分值 4/3/2/1；
A15: · 多选题（题干注明）：得分为所选选项分值之和（0/1/2 分制，选得越多分越高）；
... A23: 如需用于筛查场景，建议由专业人士复核分数段解读后再上线。

Sheet 主题总览
A1: 主题序号 | B1: 一级主题域 | C1: 测评主题 | D1: 出题风格 | E1: 题数 | F1: 维度数 | G1: 分数段数
A2: 1 | B2: 人格与个性 | C2: MBTI 16型人格 | D2: 情景选择 | E2: =COUNTIF(题目明细!$A:$A,A2) | F2: =COUNTIF(维度设置!$A:$A,A2) | G2: =COUNTIF(分数段分析!$A:$A,A2)
A3: 2 | B3: 人格与个性 | C3: MBTI维度细分（I/E、S/N、T/F、J/P） | D3: 情景选择 | E3: =COUNTIF(题目明细!$A:$A,A3) | F3: =COUNTIF(维度设置!$A:$A,A3) | G3: =COUNTIF(分数段分析!$A:$A,A3)
A4: 3 | B4: 人格与个性 | C4: 大五人格（Big Five） | D4: 情景选择 | E4: =COUNTIF(题目明细!$A:$A,A4) | F4: =COUNTIF(维度设置!$A:$A,A4) | G4: =COUNTIF(分数段分析!$A:$A,A4)
A5: 4 | B5: 人格与个性 | C5: 九型人格 | D5: 情景选择 | E5: =COUNTIF(题目明细!$A:$A,A5) | F5: =COUNTIF(维度设置!$A:$A,A5) | G5: =COUNTIF(分数段分析!$A:$A,A5)
A6: 5 | B6: 人格与个性 | C6: 艾森克人格EPQ | D6: 情景选择 | E6: =COUNTIF(题目明细!$A:$A,A6) | F6: =COUNTIF(维度设置!$A:$A,A6) | G6: =COUNTIF(分数段分析!$A:$A,A6)
A7: 6 | B7: 人格与个性 | C7: 卡特尔16PF人格因素 | D7: 情景选择 | E7: =COUNTIF(题目明细!$A:$A,A7) | F7: =COUNTIF(维度设置!$A:$A,A7) | G7: =COUNTIF(分数段分析!$A:$A,A7)
A8: 7 | B8: 人格与个性 | C8: DISC行为风格 | D8: 情景选择 | E8: =COUNTIF(题目明细!$A:$A,A8) | F8: =COUNTIF(维度设置!$A:$A,A8) | G8: =COUNTIF(分数段分析!$A:$A,A8)
A9: 8 | B9: 人格与个性 | C9: PDP性格类型 | D9: 情景选择 | E9: =COUNTIF(题目明细!$A:$A,A9) | F9: =COUNTIF(维度设置!$A:$A,A9) | G9: =COUNTIF(分数段分析!$A:$A,A9)
A10: 9 | B10: 人格与个性 | C10: FPA性格色彩 | D10: 情景选择 | E10: =COUNTIF(题目明细!$A:$A,A10) | F10: =COUNTIF(维度设置!$A:$A,A10) | G10: =COUNTIF(分数段分析!$A:$A,A10)
A11: 10 | B11: 人格与个性 | C11: 四种气质类型 | D11: 情景选择 | E11: =COUNTIF(题目明细!$A:$A,A11) | F11: =COUNTIF(维度设置!$A:$A,A11) | G11: =COUNTIF(分数段分析!$A:$A,A11)
A12: 11 | B12: 人格与个性 | C12: 菲尔人格测试 | D12: 情景选择 | E12: =COUNTIF(题目明细!$A:$A,A12) | F12: =COUNTIF(维度设置!$A:$A,A12) | G12: =COUNTIF(分数段分析!$A:$A,A12)
A13: 12 | B13: 人格与个性 | C13: 内向-外向倾向 | D13: 情景选择 | E13: =COUNTIF(题目明细!$A:$A,A13) | F13: =COUNTIF(维度设置!$A:$A,A13) | G13: =COUNTIF(分数段分析!$A:$A,A13)
... A392: 391 | B392: 投射与潜意识 | C392: 日常物品选择投射 | D392: 轻松趣味 | E392: =COUNTIF(题目明细!$A:$A,A392) | F392: =COUNTIF(维度设置!$A:$A,A392) | G392: =COUNTIF(分数段分析!$A:$A,A392)

Sheet 题目明细
A1: 主题序号 | B1: 一级主题域 | C1: 测评主题 | D1: 题号 | E1: 题干 | F1: 题型 | G1: 维度代码 | H1: 维度名称 | I1: 选项A文本 | J1: A分值 | K1: 选项B文本 | L1: B分值 | M1: 选项C文本 | N1: C分值 | O1: 选项D文本 | P1: D分值 | Q1: 选项E文本 | R1: E分值 | S1: 题目满分 | T1: 题目最低分
A2: 1 | B2: 人格与个性 | C2: MBTI 16型人格 | D2: 1 | E2: 周五晚上朋友临时约聚会，你刚到家很累，你会… | F2: 单选 | G2: D1 | H2: 能量取向 | I2: 兴奋答应还叫上朋友 | J2: 4 | K2: 推掉聚会在家安静休息 | L2: 1 | M2: 看熟人多不多再决定 | N2: 2 | O2: 先去一小时再提前撤 | P2: 3 | S2: =MAX(J2,L2,N2,P2) | T2: =MIN(J2,L2,N2,P2)
A3: 1 | B3: 人格与个性 | C3: MBTI 16型人格 | D3: 2 | E3: 到陌生城市出差，晚上有空闲，你多半… | F3: 单选 | G3: D1 | H3: 能量取向 | I3: 在酒店复盘一天的工作 | J3: 1 | K3: 去附近夜市走一走 | L3: 3 | M3: 点份外卖边吃边看剧 | N3: 2 | O3: 约当地人出来聊聊天 | P3: 4 | S3: =MAX(J3,L3,N3,P3) | T3: =MIN(J3,L3,N3,P3)
A4: 1 | B4: 人格与个性 | C4: MBTI 16型人格 | D4: 3 | E4: 连续几天独自在家办公后，你的状态通常是… | F4: 单选 | G4: D1 | H4: 能量取向 | I4: 正常，偶尔聊聊天 | J4: 2 | K4: 有点闷，想找人说话 | L4: 3 | M4: 越独处越有精神头 | N4: 1 | O4: 憋坏了，立刻约人 | P4: 4 | S4: =MAX(J4,L4,N4,P4) | T4: =MIN(J4,L4,N4,P4)
A5: 1 | B5: 人格与个性 | C5: MBTI 16型人格 | D5: 4 | E5: 团队破冰要求轮流发言，你的内心是… | F5: 单选 | G5: D1 | H5: 能量取向 | I5: 轮到就说并不紧张 | J5: 3 | K5: 盼着快点轮完坐下 | L5: 1 | M5: 提前打好简短腹稿 | N5: 2 | O5: 跃跃欲试想讲得有趣 | P5: 4 | S5: =MAX(J5,L5,N5,P5) | T5: =MIN(J5,L5,N5,P5)
A6: 1 | B6: 人格与个性 | C6: MBTI 16型人格 | D6: 5 | E6: 手机安静一整天没人找你，你会… | F6: 单选 | G6: D1 | H6: 能量取向 | I6: 翻翻群消息有点空落 | J6: 3 | K6: 主动发消息找人聊天 | L6: 4 | M6: 该干嘛干嘛不受影响 | N6: 2 | O6: 觉得清净正好专注 | P6: 1 | S6: =MAX(J6,L6,N6,P6) | T6: =MIN(J6,L6,N6,P6)
A7: 1 | B7: 人格与个性 | C7: MBTI 16型人格 | D7: 6 | E7: 婚宴上被安排到陌生同桌，一顿饭时间你会… | F7: 单选 | G7: D1 | H7: 能量取向 | I7: 带动全桌互相认识 | J7: 4 | K7: 聊得投机交换联系方式 | L7: 3 | M7: 和邻座简短寒暄几句 | N7: 2 | O7: 安静吃饭礼貌回应 | P7: 1 | S7: =MAX(J7,L7,N7,P7) | T7: =MIN(J7,L7,N7,P7)
A8: 1 | B8: 人格与个性 | C8: MBTI 16型人格 | D8: 7 | E8: 遇到烦心事或压力大的时候，你更愿意… | F8: 单选 | G8: D1 | H8: 能量取向 | I8: 关起门来独自消化 | J8: 2 | K8: 写下来自己慢慢梳理 | L8: 1 | M8: 见到熟人就想倾诉 | N8: 4 | O8: 找一两个信任的人说 | P8: 3 | S8: =MAX(J8,L8,N8,P8) | T8: =MIN(J8,L8,N8,P8)
A9: 1 | B9: 人格与个性 | C9: MBTI 16型人格 | D9: 8 | E9: 想弄清一份体检报告的细节，你会… | F9: 单选 | G9: D1 | H9: 能量取向 | I9: 拉懂医的朋友一起看 | J9: 3 | K9: 记下来下次问医生 | L9: 2 | M9: 上网逐条查资料 | N9: 1 | O9: 发到群里集思广益 | P9: 4 | S9: =MAX(J9,L9,N9,P9) | T9: =MIN(J9,L9,N9,P9)
A10: 1 | B10: 人格与个性 | C10: MBTI 16型人格 | D10: 9 | E10: 周末大扫除时，你更享受… | F10: 单选 | G10: D1 | H10: 能量取向 | I10: 家人各自分工不打扰 | J10: 2 | K10: 一个人边听歌边干活 | L10: 1 | M10: 边干活边和家人闲聊 | N10: 3 | O10: 叫上朋友一起动手 | P10: 4 | S10: =MAX(J10,L10,N10,P10) | T10: =MIN(J10,L10,N10,P10)
A11: 1 | B11: 人格与个性 | C11: MBTI 16型人格 | D11: 10 | E11: 参加一场陌生的行业酒会，你通常… | F11: 单选 | G11: D1 | H11: 能量取向 | I11: 换几个人各聊上几句 | J11: 3 | K11: 和陌生人聊得火热 | L11: 4 | M11: 只和认识的人待一起 | N11: 2 | O11: 找角落待够时间就走 | P11: 1 | S11: =MAX(J11,L11,N11,P11) | T11: =MIN(J11,L11,N11,P11)
A12: 1 | B12: 人格与个性 | C12: MBTI 16型人格 | D12: 11 | E12: 学习一项新技能，你更偏爱… | F12: 单选 | G12: D1 | H12: 能量取向 | I12: 看录播慢慢消化 | J12: 2 | K12: 直接报班融入班级 | L12: 4 | M12: 找学习搭子互相打卡 | N12: 3 | O12: 看教程自己反复练 | P12: 1 | S12: =MAX(J12,L12,N12,P12) | T12: =MIN(J12,L12,N12,P12)
A13: 1 | B13: 人格与个性 | C13: MBTI 16型人格 | D13: 12 | E13: 旅行时遇到健谈的当地人，你的反应是… | F13: 单选 | G13: D1 | H13: 能量取向 | I13: 简单应答两句道别 | J13: 2 | K13: 一聊半小时互加好友 | L13: 4 | M13: 顺着聊起风土人情 | N13: 3 | O13: 礼貌点头继续赶路 | P13: 1 | S13: =MAX(J13,L13,N13,P13) | T13: =MIN(J13,L13,N13,P13)
... A2987: 100 | B2987: 婚姻与家庭 | C2987: 离婚倾向与动机 | D2987: 7 | E2987: 当你生病或情绪低落时，伴侣的表现通常是： | F2987: 单选 | G2987: D1 | H2987: 婚姻满意度 | I2987: 会关心但方式笨拙 | J2987: 3 | K2987: 细心照顾耐心陪伴 | L2987: 4 | M2987: 问一句就忙自己的 | N2987: 2 | O2987: 察觉不到我的状态 | P2987: 1 | S2987: =MAX(J2987,L2987,N2987,P2987) | T2987: =MIN(J2987,L2987,N2987,P2987)
A2988: 100 | B2988: 婚姻与家庭 | C2988: 离婚倾向与动机 | D2988: 8 | E2988: 以下哪些描述更贴近你目前的婚姻状态（多选）： | F2988: 多选 | G2988: D1 | H2988: 婚姻满意度 | I2988: 保留专属的小默契 | J2988: 2 | K2988: 偶有心动瞬间闪回 | L2988: 1 | M2988: 相处像合租的室友 | N2988: 0 | O2988: 想起对方先想到烦 | P2988: 0 | Q2988: 仍愿意为关系花心思 | R2988: 2 | S2988: =MAX(J2988,L2988,N2988,P2988,R2988) | T2988: =MIN(J2988,L2988,N2988,P2988,R2988)
A2989: 100 | B2989: 婚姻与家庭 | C2989: 离婚倾向与动机 | D2989: 9 | E2989: 激烈争吵到最凶的时候，你一般会怎么做： | F2989: 单选 | G2989: D2 | H2989: 冲突修复能力 | I2989: 喊暂停冷静再谈 | J2989: 4 | K2989: 翻旧账往痛处说 | L2989: 1 | M2989: 闭嘴忍着不吭声 | N2989: 3 | O2989: 摔门离开不回头 | P2989: 2 | S2989: =MAX(J2989,L2989,N2989,P2989) | T2989: =MIN(J2989,L2989,N2989,P2989)
A2990: 100 | B2990: 婚姻与家庭 | C2990: 离婚倾向与动机 | D2990: 10 | E2990: 吵完架的当天晚上，通常是谁先缓和气氛： | F2990: 单选 | G2990: D2 | H2990: 冲突修复能力 | I2990: 总得有人递台阶 | J2990: 2 | K2990: 我们很快互相搭话 | L2990: 4 | M2990: 先低头的人是我 | N2990: 3 | O2990: 常常僵持好几天 | P2990: 1 | S2990: =MAX(J2990,L2990,N2990,P2990) | T2990: =MIN(J2990,L2990,N2990,P2990)
A2991: 100 | B2991: 婚姻与家庭 | C2991: 离婚倾向与动机 | D2991: 11 | E2991: 对同一件事反复起冲突时，你们会： | F2991: 单选 | G2991: D2 | H2991: 冲突修复能力 | I2991: 只提醒不深谈 | J2991: 3 | K2991: 等对方先改变 | L2991: 2 | M2991: 试着找折中方案 | N2991: 4 | O2991: 吵完就过下次再吵 | P2991: 1 | S2991: =MAX(J2991,L2991,N2991,P2991) | T2991: =MIN(J2991,L2991,N2991,P2991)
A2992: 100 | B2992: 婚姻与家庭 | C2992: 离婚倾向与动机 | D2992: 12 | E2992: 冷静之后复盘吵架原因，你的习惯是： | F2992: 单选 | G2992: D2 | H2992: 冲突修复能力 | I2992: 从不想那些糟心事 | J2992: 1 | K2992: 想想就算了不说出 | L2992: 2 | M2992: 找机会把感受说开 | N2992: 4 | O2992: 跟朋友吐槽取建议 | P2992: 3 | S2992: =MAX(J2992,L2992,N2992,P2992) | T2992: =MIN(J2992,L2992,N2992,P2992)
A2993: 100 | B2993: 婚姻与家庭 | C2993: 离婚倾向与动机 | D2993: 13 | E2993: 对方主动道歉或示好时，你的第一反应通常是： | F2993: 单选 | G2993: D2 | H2993: 冲突修复能力 | I2993: 接受但仍有点别扭 | J2993: 3 | K2993: 继续冷着脸不理 | L2993: 1 | M2993: 顺势接住握手言和 | N2993: 4 | O2993: 嘴上说没事心里堵 | P2993: 2 | S2993: =MAX(J2993,L2993,N2993,P2993) | T2993: =MIN(J2993,L2993,N2993,P2993)
A2994: 100 | B2994: 婚姻与家庭 | C2994: 离婚倾向与动机 | D2994: 14 | E2994: 面对暂时解不开的分歧，你的态度是： | F2994: 单选 | G2994: D2 | H2994: 冲突修复能力 | I2994: 认定无法调和了 | J2994: 1 | K2994: 必须马上争出对错 | L2994: 2 | M2994: 允许先放放再谈 | N2994: 4 | O2994: 各自保留互不干涉 | P2994: 3 | S2994: =MAX(J2994,L2994,N2994,P2994) | T2994: =MIN(J2994,L2994,N2994,P2994)
A2995: 100 | B2995: 婚姻与家庭 | C2995: 离婚倾向与动机 | D2995: 15 | E2995: 当你意识到自己也有错时，通常会： | F2995: 单选 | G2995: D2 | H2995: 冲突修复能力 | I2995: 找机会坦诚认错 | J2995: 4 | K2995: 用行动悄悄弥补 | L2995: 3 | M2995: 绝不肯先低头 | N2995: 1 | O2995: 心里认嘴上不认 | P2995: 2 | S2995: =MAX(J2995,L2995,N2995,P2995) | T2995: =MIN(J2995,L2995,N2995,P2995)
A2996: 100 | B2996: 婚姻与家庭 | C2996: 离婚倾向与动机 | D2996: 16 | E2996: 外部压力大的时候（工作不顺等），你们的相处会： | F2996: 单选 | G2996: D2 | H2996: 冲突修复能力 | I2996: 互相体谅共渡难关 | J2996: 4 | K2996: 容易把火撒给对方 | L2996: 1 | M2996: 话变少但不出恶语 | N2996: 3 | O2996: 频繁冷战互相指责 | P2996: 2 | S2996: =MAX(J2996,L2996,N2996,P2996) | T2996: =MIN(J2996,L2996,N2996,P2996)
A2997: 100 | B2997: 婚姻与家庭 | C2997: 离婚倾向与动机 | D2997: 17 | E2997: 深夜独处时，离婚这个念头在你脑中： | F2997: 单选 | G2997: D3 | H2997: 分离念头与动机 | I2997: 很少出现闪过就过 | J2997: 4 | K2997: 反复盘算具体细节 | L2997: 1 | M2997: 偶尔想起让人烦躁 | N2997: 2 | O2997: 烦心事多时才冒出 | P2997: 3 | S2997: =MAX(J2997,L2997,N2997,P2997) | T2997: =MIN(J2997,L2997,N2997,P2997)
A2998: 100 | B2998: 婚姻与家庭 | C2998: 离婚倾向与动机 | D2998: 18 | E2998: 你考虑过离婚的主要原因是： | F2998: 单选 | G2998: D3 | H2998: 分离念头与动机 | I2998: 没认真想过这事 | J2998: 4 | K2998: 一气之下的冲动 | L2998: 3 | M2998: 长期的失望和委屈 | N2998: 1 | O2998: 性格不合沟通困难 | P2998: 2 | S2998: =MAX(J2998,L2998,N2998,P2998) | T2998: =MIN(J2998,L2998,N2998,P2998)
A2999: 100 | B2999: 婚姻与家庭 | C2999: 离婚倾向与动机 | D2999: 19 | E2999: 如果让你列举必须离婚的硬理由，你能列： | F2999: 单选 | G2999: D3 | H2999: 分离念头与动机 | I2999: 一长串难以辩驳 | J2999: 1 | K2999: 只有情绪上来时能列 | L2999: 2 | M2999: 其实一条也说不清 | N2999: 4 | O2999: 两三条都不算硬 | P2999: 3 | S2999: =MAX(J2999,L2999,N2999,P2999) | T2999: =MIN(J2999,L2999,N2999,P2999)
A3000: 100 | B3000: 婚姻与家庭 | C3000: 离婚倾向与动机 | D3000: 20 | E3000: 身边人劝和或劝分时，你内心的真实倾向： | F3000: 单选 | G3000: D3 | H3000: 分离念头与动机 | I3000: 听完会再想想再定 | J3000: 3 | K3000: 只信自己的判断 | L3000: 4 | M3000: 希望有人替我决定 | N3000: 1 | O3000: 谁的话都容易动摇 | P3000: 2 | S3000: =MAX(J3000,L3000,N3000,P3000) | T3000: =MIN(J3000,L3000,N3000,P3000)
... A3002: 100 | B3002: 婚姻与家庭 | C3002: 离婚倾向与动机 | D3002: 22 | E3002: 当你想象未来五年的生活画面时，画面里： | F3002: 单选 | G3002: D3 | H3002: 分离念头与动机 | I3002: 有家但气氛冷清 | J3002: 3 | K3002: 很模糊不敢细想 | L3002: 2 | M3002: 只有我一个人 | N3002: 1 | O3002: 有伴侣也有共同目标 | P3002: 4 | S3002: =MAX(J3002,L3002,N3002,P3002) | T3002: =MIN(J3002,L3002,N3002,P3002)
A3003: 100 | B3003: 婚姻与家庭 | C3003: 离婚倾向与动机 | D3003: 23 | E3003: 以下哪些情况最近半年你经历过（多选）： | F3003: 多选 | G3003: D3 | H3003: 分离念头与动机 | I3003: 冷战超过一个星期 | J3003: 0 | K3003: 为对方做过暖心小事 | L3003: 2 | M3003: 认真查过离婚手续 | N3003: 0 | O3003: 向人吐槽过想离婚 | P3003: 0 | Q3003: 和伴侣有过开心出游 | R3003: 2 | S3003: =MAX(J3003,L3003,N3003,P3003,R3003) | T3003: =MIN(J3003,L3003,N3003,P3003,R3003)
A3004: 100 | B3004: 婚姻与家庭 | C3004: 离婚倾向与动机 | D3004: 24 | E3004: 如果现在有一档修复婚姻的机会（如咨询），你会： | F3004: 单选 | G3004: D3 | H3004: 分离念头与动机 | I3004: 愿意拉上对方试试 | J3004: 4 | K3004: 先观望对方的态度 | L3004: 2 | M3004: 觉得没用直接拒绝 | N3004: 1 | O3004: 自己先了解着看 | P3004: 3 | S3004: =MAX(J3004,L3004,N3004,P3004) | T3004: =MIN(J3004,L3004,N3004,P3004)
A3005: 101 | B3005: 婚姻与家庭 | C3005: 婚姻第三者风险 | D3005: 1 | E3005: 最近半年，你和伴侣深聊心事和感受的频率是： | F3005: 单选 | G3005: D1 | H3005: 情感投入度 | I3005: 几乎每周都有 | J3005: 4 | K3005: 一个月一两次 | L3005: 3 | M3005: 想不起来何时聊过 | N3005: 1 | O3005: 只在有事时才交谈 | P3005: 2 | S3005: =MAX(J3005,L3005,N3005,P3005) | T3005: =MIN(J3005,L3005,N3005,P3005)
A3006: 101 | B3006: 婚姻与家庭 | C3006: 婚姻第三者风险 | D3006: 2 | E3006: 遇到开心的事，你的第一反应是告诉谁： | F3006: 单选 | G3006: D1 | H3006: 情感投入度 | I3006: 伴侣永远排在首位 | J3006: 4 | K3006: 发到群里谁回算谁 | L3006: 2 | M3006: 看场合在伴侣朋友间切换 | N3006: 3 | O3006: 某位异性朋友更懂我 | P3006: 1 | S3006: =MAX(J3006,L3006,N3006,P3006) | T3006: =MIN(J3006,L3006,N3006,P3006)
A3007: 101 | B3007: 婚姻与家庭 | C3007: 婚姻第三者风险 | D3007: 3 | E3007: 你们上一次专门的二人约会或旅行是什么时候： | F3007: 单选 | G3007: D1 | H3007: 情感投入度 | I3007: 近两个月就有安排 | J3007: 4 | K3007: 一年以上或从没有 | L3007: 1 | M3007: 约过但总被搁置 | N3007: 2 | O3007: 半年之内有过 | P3007: 3 | S3007: =MAX(J3007,L3007,N3007,P3007) | T3007: =MIN(J3007,L3007,N3007,P3007)
A3008: 101 | B3008: 婚姻与家庭 | C3008: 婚姻第三者风险 | D3008: 4 | E3008: 伴侣情绪低落时，你能敏锐察觉并主动过问吗： | F3008: 单选 | G3008: D1 | H3008: 情感投入度 | I3008: 常常后知后觉 | J3008: 2 | K3008: 对方说了我才会管 | L3008: 1 | M3008: 多数时候能留意到 | N3008: 3 | O3008: 总能第一时间发现 | P3008: 4 | S3008: =MAX(J3008,L3008,N3008,P3008) | T3008: =MIN(J3008,L3008,N3008,P3008)
A3009: 101 | B3009: 婚姻与家庭 | C3009: 婚姻第三者风险 | D3009: 5 | E3009: 你对婚姻现状的情感浓度，更接近哪种形容： | F3009: 单选 | G3009: D1 | H3009: 情感投入度 | I3009: 老夫老妻般安稳 | J3009: 3 | K3009: 时好时坏说不清 | L3009: 2 | M3009: 亲密感仍在持续升温 | N3009: 4 | O3009: 越来越像陌生人 | P3009: 1 | S3009: =MAX(J3009,L3009,N3009,P3009) | T3009: =MIN(J3009,L3009,N3009,P3009)
A3010: 101 | B3010: 婚姻与家庭 | C3010: 婚姻第三者风险 | D3010: 6 | E3010: 工作再忙，你也会专门留出陪伴伴侣的时间吗： | F3010: 单选 | G3010: D1 | H3010: 情感投入度 | I3010: 想起来才安排 | J3010: 2 | K3010: 尽量留偶尔失守 | L3010: 3 | M3010: 固定留且雷打不动 | N3010: 4 | O3010: 忙起来就完全牺牲 | P3010: 1 | S3010: =MAX(J3010,L3010,N3010,P3010) | T3010: =MIN(J3010,L3010,N3010,P3010)
A3011: 101 | B3011: 婚姻与家庭 | C3011: 婚姻第三者风险 | D3011: 7 | E3011: 身体接触（牵手拥抱等）在你们的日常中： | F3011: 单选 | G3011: D1 | H3011: 情感投入度 | I3011: 很久没有过了 | J3011: 1 | K3011: 频率不高但不排斥 | L3011: 3 | M3011: 自然发生习以为常 | N3011: 4 | O3011: 节日时才会有 | P3011: 2 | S3011: =MAX(J3011,L3011,N3011,P3011) | T3011: =MIN(J3011,L3011,N3011,P3011)
A3012: 101 | B3012: 婚姻与家庭 | C3012: 婚姻第三者风险 | D3012: 8 | E3012: 你和伴侣争吵后的和解，通常是怎么达成的： | F3012: 单选 | G3012: D1 | H3012: 情感投入度 | I3012: 拖几天才慢慢缓和 | J3012: 2 | K3012: 快速和好很快如常 | L3012: 4 | M3012: 总有一方冷淡到底 | N3012: 1 | O3012: 需要外人从中劝解 | P3012: 3 | S3012: =MAX(J3012,L3012,N3012,P3012) | T3012: =MIN(J3012,L3012,N3012,P3012)
A3013: 101 | B3013: 婚姻与家庭 | C3013: 婚姻第三者风险 | D3013: 9 | E3013: 异性同事深夜发来情绪化的倾诉消息，你会： | F3013: 单选 | G3013: D2 | H3013: 边界与自律 | I3013: 耐心陪聊到深夜 | J3013: 1 | K3013: 觉得正常正常回复 | L3013: 2 | M3013: 转告伴侣并减少私聊 | N3013: 4 | O3013: 简短回复转移话题 | P3013: 3 | S3013: =MAX(J3013,L3013,N3013,P3013) | T3013: =MIN(J3013,L3013,N3013,P3013)
A3014: 101 | B3014: 婚姻与家庭 | C3014: 婚姻第三者风险 | D3014: 10 | E3014: 有人对你表达暧昧好感时，你的处理方式是： | F3014: 单选 | G3014: D2 | H3014: 边界与自律 | I3014: 婉拒但继续做朋友 | J3014: 3 | K3014: 明确拒绝不留余地 | L3014: 4 | M3014: 享受被关注的感觉 | N3014: 1 | O3014: 装作看不懂拖着 | P3014: 2 | S3014: =MAX(J3014,L3014,N3014,P3014) | T3014: =MIN(J3014,L3014,N3014,P3014)
...

Sheet 维度设置
A1: 主题序号 | B1: 测评主题 | C1: 维度代码 | D1: 维度名称 | E1: 维度说明 | F1: 题目数 | G1: 包含题号 | H1: 维度最低分 | I1: 维度总分
A2: 1 | B2: MBTI 16型人格 | C2: D1 | D2: 能量取向 | E2: 在独处充电与社交互动间的精力偏好，高分偏外向。 | F2: =COUNTIFS(题目明细!$A:$A,A2,题目明细!$G:$G,C2) | G2: 1、2、3、4、5、6、7、8、9、10、11、12、13、14、15、16、17、18、19、20、21、22 | H2: =SUMIFS(题目明细!$T:$T,题目明细!$A:$A,A2,题目明细!$G:$G,C2) | I2: =SUMIFS(题目明细!$S:$S,题目明细!$A:$A,A2,题目明细!$G:$G,C2)
A3: 1 | B3: MBTI 16型人格 | C3: D2 | D3: 信息获取 | E3: 接收信息时偏重事实细节还是联想与可能，高分偏直觉。 | F3: =COUNTIFS(题目明细!$A:$A,A3,题目明细!$G:$G,C3) | G3: 23、24、25、26、27、28、29、30、31、32、33、34、35、36、37、38、39、40、41、42、43、44 | H3: =SUMIFS(题目明细!$T:$T,题目明细!$A:$A,A3,题目明细!$G:$G,C3) | I3: =SUMIFS(题目明细!$S:$S,题目明细!$A:$A,A3,题目明细!$G:$G,C3)
A4: 1 | B4: MBTI 16型人格 | C4: D3 | D4: 决策方式 | E4: 做判断时偏重逻辑一致还是人际情感，高分偏情感。 | F4: =COUNTIFS(题目明细!$A:$A,A4,题目明细!$G:$G,C4) | G4: 45、46、47、48、49、50、51、52、53、54、55、56、57、58、59、60、61、62、63、64、65、66 | H4: =SUMIFS(题目明细!$T:$T,题目明细!$A:$A,A4,题目明细!$G:$G,C4) | I4: =SUMIFS(题目明细!$S:$S,题目明细!$A:$A,A4,题目明细!$G:$G,C4)
A5: 1 | B5: MBTI 16型人格 | C5: D4 | D5: 生活态度 | E5: 对待计划、秩序与变化的基本倾向，高分偏计划性。 | F5: =COUNTIFS(题目明细!$A:$A,A5,题目明细!$G:$G,C5) | G5: 67、68、69、70、71、72、73、74、75、76、77、78、79、80、81、82、83、84、85、86、87、88 | H5: =SUMIFS(题目明细!$T:$T,题目明细!$A:$A,A5,题目明细!$G:$G,C5) | I5: =SUMIFS(题目明细!$S:$S,题目明细!$A:$A,A5,题目明细!$G:$G,C5)
A6: 2 | B6: MBTI维度细分（I/E、S/N、T/F、J/P） | C6: D1 | D6: 能量来源 | E6: 精力主要来自独处还是人群互动，高分偏外向。 | F6: =COUNTIFS(题目明细!$A:$A,A6,题目明细!$G:$G,C6) | G6: 1、2、3、4、5、6、7、8、9、10 | H6: =SUMIFS(题目明细!$T:$T,题目明细!$A:$A,A6,题目明细!$G:$G,C6) | I6: =SUMIFS(题目明细!$S:$S,题目明细!$A:$A,A6,题目明细!$G:$G,C6)
A7: 2 | B7: MBTI维度细分（I/E、S/N、T/F、J/P） | C7: D2 | D7: 感知偏好 | E7: 接收信息时偏重具体经验还是联想可能，高分偏直觉。 | F7: =COUNTIFS(题目明细!$A:$A,A7,题目明细!$G:$G,C7) | G7: 11、12、13、14、15、16、17、18、19、20 | H7: =SUMIFS(题目明细!$T:$T,题目明细!$A:$A,A7,题目明细!$G:$G,C7) | I7: =SUMIFS(题目明细!$S:$S,题目明细!$A:$A,A7,题目明细!$G:$G,C7)
A8: 2 | B8: MBTI维度细分（I/E、S/N、T/F、J/P） | C8: D3 | D8: 判断与计划 | E8: 决策时偏逻辑还是共情、执行偏弹性还是计划，高分偏共情与计划。 | F8: =COUNTIFS(题目明细!$A:$A,A8,题目明细!$G:$G,C8) | G8: 21、22、23、24、25、26、27、28、29、30 | H8: =SUMIFS(题目明细!$T:$T,题目明细!$A:$A,A8,题目明细!$G:$G,C8) | I8: =SUMIFS(题目明细!$S:$S,题目明细!$A:$A,A8,题目明细!$G:$G,C8)
A9: 3 | B9: 大五人格（Big Five） | C9: D1 | D9: 经验开放 | E9: 对新观念、新体验与抽象事物的兴趣和接纳度。 | F9: =COUNTIFS(题目明细!$A:$A,A9,题目明细!$G:$G,C9) | G9: 1、2、3、4、5、6、7、8、9、10、11、12、13、14、15 | H9: =SUMIFS(题目明细!$T:$T,题目明细!$A:$A,A9,题目明细!$G:$G,C9) | I9: =SUMIFS(题目明细!$S:$S,题目明细!$A:$A,A9,题目明细!$G:$G,C9)
A10: 3 | B10: 大五人格（Big Five） | C10: D2 | D10: 自律尽责 | E10: 目标感、条理性与对承诺和细节的把控程度。 | F10: =COUNTIFS(题目明细!$A:$A,A10,题目明细!$G:$G,C10) | G10: 16、17、18、19、20、21、22、23、24、25、26、27、28、29、30 | H10: =SUMIFS(题目明细!$T:$T,题目明细!$A:$A,A10,题目明细!$G:$G,C10) | I10: =SUMIFS(题目明细!$S:$S,题目明细!$A:$A,A10,题目明细!$G:$G,C10)
A11: 3 | B11: 大五人格（Big Five） | C11: D3 | D11: 人际温度 | E11: 与人相处时的热情、体贴与合作倾向。 | F11: =COUNTIFS(题目明细!$A:$A,A11,题目明细!$G:$G,C11) | G11: 31、32、33、34、35、36、37、38、39、40、41、42、43、44、45 | H11: =SUMIFS(题目明细!$T:$T,题目明细!$A:$A,A11,题目明细!$G:$G,C11) | I11: =SUMIFS(题目明细!$S:$S,题目明细!$A:$A,A11,题目明细!$G:$G,C11)
A12: 3 | B12: 大五人格（Big Five） | C12: D4 | D12: 情绪稳定 | E12: 面对压力与突发状况时的情绪波动与恢复力。 | F12: =COUNTIFS(题目明细!$A:$A,A12,题目明细!$G:$G,C12) | G12: 46、47、48、49、50、51、52、53、54、55、56、57、58、59、60 | H12: =SUMIFS(题目明细!$T:$T,题目明细!$A:$A,A12,题目明细!$G:$G,C12) | I12: =SUMIFS(题目明细!$S:$S,题目明细!$A:$A,A12,题目明细!$G:$G,C12)
A13: 4 | B13: 九型人格 | C13: D1 | D13: 原则与责任 | E13: 对标准、规则与正确性的坚持程度，高分偏完美倾向。 | F13: =COUNTIFS(题目明细!$A:$A,A13,题目明细!$G:$G,C13) | G13: 1、2、3、4、5、6、7、8、9、10、11、12、13、14、15 | H13: =SUMIFS(题目明细!$T:$T,题目明细!$A:$A,A13,题目明细!$G:$G,C13) | I13: =SUMIFS(题目明细!$S:$S,题目明细!$A:$A,A13,题目明细!$G:$G,C13)
... A1187: 391 | B1187: 日常物品选择投射 | C1187: D3 | D1187: 选择风格 | E1187: 物品与金钱决策中体现的自主性与消费理性 | F1187: =COUNTIFS(题目明细!$A:$A,A1187,题目明细!$G:$G,C1187) | G1187: 15、16、17、18、19、20、21 | H1187: =SUMIFS(题目明细!$T:$T,题目明细!$A:$A,A1187,题目明细!$G:$G,C1187) | I1187: =SUMIFS(题目明细!$S:$S,题目明细!$A:$A,A1187,题目明细!$G:$G,C1187)

Sheet 分数段分析
A1: 主题序号 | B1: 测评主题 | C1: 维度代码 | D1: 维度名称 | E1: 分数段 | F1: 下限 | G1: 上限 | H1: 评级 | I1: 分析 | J1: 建议
A2: 1 | B2: MBTI 16型人格 | C2: D1 | D2: 能量取向 | E2: 第1段 | F2: 20 | G2: 41 | H2: 低位 | I2: 内向倾向明显，独处时精力最充沛，热闹场合后需要独处回血，在少数深度关系里更自在。 | J2: 不必强迫自己合群，把社交按重要程度分配额度，优先维护少数高质量关系，活动后预留恢复时间。
A3: 1 | B3: MBTI 16型人格 | C3: D1 | D3: 能量取向 | E3: 第2段 | F3: 42 | G3: 63 | H3: 中位 | I3: 处于中间偏灵活的位置，独处与社交都能适应，但长时间偏向任何一侧都会感到疲惫或乏味。 | J3: 觉察每周的能量消耗节奏，交替安排独处充电与轻量社交，给两种模式都留出固定空间。定期做一次小复盘，微调节奏就能持续精进。
A4: 1 | B4: MBTI 16型人格 | C4: D1 | D4: 能量取向 | E4: 第3段 | F4: 64 | G4: 89 | H4: 高位 | I4: 外向倾向明显，与人互动让你充满电，主动健谈，人群中常是活跃与连接的担当。这一特质常是你的核心竞争力，值得有意识地经营与发挥。 | J4: 发挥连接者优势，多承担组织与协作角色，同时练习安静倾听，避免热情淹没他人的表达空间。
A5: 1 | B5: MBTI 16型人格 | C5: D2 | D5: 信息获取 | E5: 第1段 | F5: 20 | G5: 41 | H5: 低位 | I5: 偏实感风格，关注事实、细节与当下经验，讲究可验证可落地，观察力和执行力比较扎实。 | J5: 踏实是你的优势，遇到抽象议题时先追问它想解决什么问题，再落回具体步骤，逐步适应概念思维。
A6: 1 | B6: MBTI 16型人格 | C6: D2 | D6: 信息获取 | E6: 第2段 | F6: 42 | G6: 63 | H6: 中位 | I6: 能在细节与全局之间切换，既关注实际情况也乐于联想，理解抽象概念不算费力。多数场景下你应对得当，出现的波动基本属于正常范围。 | J6: 用一栏事实清单加一栏愿景设想的笔记方式，让两种思维各司其职，互补短板。定期做一次小复盘，微调节奏就能持续精进。
A7: 1 | B7: MBTI 16型人格 | C7: D2 | D7: 信息获取 | E7: 第3段 | F7: 64 | G7: 89 | H7: 高位 | I7: 偏直觉风格，联想快、点子多，容易被新的可能性吸引，对比喻、趋势和未来图景敏感。这一特质常是你的核心竞争力，值得有意识地经营与发挥。 | J7: 把灵感及时转成步骤与时间点，定期向注重细节的伙伴求证，防止好想法悬在空中落不了地。
A8: 1 | B8: MBTI 16型人格 | C8: D3 | D8: 决策方式 | E8: 第1段 | F8: 20 | G8: 41 | H8: 低位 | I8: 偏思考风格，决策讲逻辑、重标准，对事不对人，能在压力下保持客观和一致的判断。这种状态很常见，通常只反映当下的默认模式，并非固定不变的特质。 | J8: 传达结论时先接住对方处境再摆逻辑，在重要关系里练习先回应感受，再给出方案。从最小的行动开始，坚持两三周并用记录看见变化。
A9: 1 | B9: MBTI 16型人格 | C9: D3 | D9: 决策方式 | E9: 第2段 | F9: 42 | G9: 63 | H9: 中位 | I9: 决策时既讲道理也顾人情，能依据场合在客观分析与人际考量之间来回权衡。多数场景下你应对得当，出现的波动基本属于正常范围。 | J9: 事务性决定多用理性框架，涉及他人情绪的重大事项时，多问一句你希望我怎么帮你。定期做一次小复盘，微调节奏就能持续精进。
A10: 1 | B10: MBTI 16型人格 | C10: D3 | D10: 决策方式 | E10: 第3段 | F10: 64 | G10: 89 | H10: 高位 | I10: 偏情感风格，重视和谐与他人感受，同理心强，决策时常把人的因素放在事情前面。这一特质常是你的核心竞争力，值得有意识地经营与发挥。 | J10: 练习用数据和标准支撑善意决策，对不合理请求明确说不，避免过度共情造成自我消耗。记得定期自我复盘，防止优势在惯性里变成盲区。
A11: 1 | B11: MBTI 16型人格 | C11: D4 | D11: 生活态度 | E11: 第1段 | F11: 20 | G11: 41 | H11: 低位 | I11: 偏知觉风格，喜欢保留选择权，随遇而安，临场应变快，容易被死板的流程和承诺束缚。这种状态很常见，通常只反映当下的默认模式，并非固定不变的特质。 | J11: 只给关键事项设硬性节点，其余保留弹性，用提醒工具兜底，避免遗漏重要承诺。从最小的行动开始，坚持两三周并用记录看见变化。
A12: 1 | B12: MBTI 16型人格 | C12: D4 | D12: 生活态度 | E12: 第2段 | F12: 42 | G12: 63 | H12: 中位 | I12: 张弛有度，既能提前规划也能接受变化，多数时候在秩序与灵活之间自然调节。多数场景下你应对得当，出现的波动基本属于正常范围。 | J12: 把事项分成必须准时和可以随缘两档管理，让计划为生活服务，而不是被计划牵着走。定期做一次小复盘，微调节奏就能持续精进。
A13: 1 | B13: MBTI 16型人格 | C13: D4 | D13: 生活态度 | E13: 第3段 | F13: 64 | G13: 89 | H13: 高位 | I13: 偏判断风格，喜欢清单、日程与确定性，做事有头有尾，未完成事项容易一直挂在心上。这一特质常是你的核心竞争力，值得有意识地经营与发挥。 | J13: 给计划留出缓冲带，每周留一段无安排时间，在小事上练习即兴，降低对突变的应激反应。
... A3690: 391 | B3690: 日常物品选择投射 | C3690: D3 | D3690: 选择风格 | E3690: 第3段 | F3690: 22 | G3690: 29 | H3690: 高位 | I3690: 你的选择清晰自主，买与不买都出于真实需要，与物品的关系松弛清明，界限分明，互不绑架。 | J3690: 保持这份难得的清明，也可以帮家人朋友把关大件消费，让经验产生更大的价值，人见人夸。
